Traceback (most recent call last):
  File "/Users/jordivilla/miniconda3/lib/python3.11/site-packages/jupyter_cache/executors/utils.py", line 58, in single_nb_execution
    executenb(
  File "/Users/jordivilla/miniconda3/lib/python3.11/site-packages/nbclient/client.py", line 1204, in execute
    return NotebookClient(nb=nb, resources=resources, km=km, **kwargs).execute()
           ^^^^^^^^^^^^^^^^^^^^^^^^^^^^^^^^^^^^^^^^^^^^^^^^^^^^^^^^^^^^^^^^^^^^^
  File "/Users/jordivilla/miniconda3/lib/python3.11/site-packages/nbclient/util.py", line 84, in wrapped
    return just_run(coro(*args, **kwargs))
           ^^^^^^^^^^^^^^^^^^^^^^^^^^^^^^^
  File "/Users/jordivilla/miniconda3/lib/python3.11/site-packages/nbclient/util.py", line 62, in just_run
    return loop.run_until_complete(coro)
           ^^^^^^^^^^^^^^^^^^^^^^^^^^^^^
  File "/Users/jordivilla/miniconda3/lib/python3.11/asyncio/base_events.py", line 653, in run_until_complete
    return future.result()
           ^^^^^^^^^^^^^^^
  File "/Users/jordivilla/miniconda3/lib/python3.11/site-packages/nbclient/client.py", line 663, in async_execute
    await self.async_execute_cell(
  File "/Users/jordivilla/miniconda3/lib/python3.11/site-packages/nbclient/client.py", line 965, in async_execute_cell
    await self._check_raise_for_error(cell, cell_index, exec_reply)
  File "/Users/jordivilla/miniconda3/lib/python3.11/site-packages/nbclient/client.py", line 862, in _check_raise_for_error
    raise CellExecutionError.from_cell_and_msg(cell, exec_reply_content)
nbclient.exceptions.CellExecutionError: An error occurred while executing the following cell:
------------------
#data = data.loc[:,('Adj Close', slice(None))]
data.columns = assets
data.head()
------------------

[0;31m---------------------------------------------------------------------------[0m
[0;31mValueError[0m                                Traceback (most recent call last)
Cell [0;32mIn[3], line 2[0m
[1;32m      1[0m [38;5;66;03m#data = data.loc[:,('Adj Close', slice(None))][39;00m
[0;32m----> 2[0m data[38;5;241m.[39mcolumns [38;5;241m=[39m assets
[1;32m      3[0m data[38;5;241m.[39mhead()

File [0;32m~/miniconda3/lib/python3.11/site-packages/pandas/core/generic.py:6002[0m, in [0;36mNDFrame.__setattr__[0;34m(self, name, value)[0m
[1;32m   6000[0m [38;5;28;01mtry[39;00m:
[1;32m   6001[0m     [38;5;28mobject[39m[38;5;241m.[39m[38;5;21m__getattribute__[39m([38;5;28mself[39m, name)
[0;32m-> 6002[0m     [38;5;28;01mreturn[39;00m [38;5;28mobject[39m[38;5;241m.[39m[38;5;21m__setattr__[39m([38;5;28mself[39m, name, value)
[1;32m   6003[0m [38;5;28;01mexcept[39;00m [38;5;167;01mAttributeError[39;00m:
[1;32m   6004[0m     [38;5;28;01mpass[39;00m

File [0;32m~/miniconda3/lib/python3.11/site-packages/pandas/_libs/properties.pyx:69[0m, in [0;36mpandas._libs.properties.AxisProperty.__set__[0;34m()[0m

File [0;32m~/miniconda3/lib/python3.11/site-packages/pandas/core/generic.py:730[0m, in [0;36mNDFrame._set_axis[0;34m(self, axis, labels)[0m
[1;32m    725[0m [38;5;250m[39m[38;5;124;03m"""[39;00m
[1;32m    726[0m [38;5;124;03mThis is called from the cython code when we set the `index` attribute[39;00m
[1;32m    727[0m [38;5;124;03mdirectly, e.g. `series.index = [1, 2, 3]`.[39;00m
[1;32m    728[0m [38;5;124;03m"""[39;00m
[1;32m    729[0m labels [38;5;241m=[39m ensure_index(labels)
[0;32m--> 730[0m [38;5;28mself[39m[38;5;241m.[39m_mgr[38;5;241m.[39mset_axis(axis, labels)
[1;32m    731[0m [38;5;28mself[39m[38;5;241m.[39m_clear_item_cache()

File [0;32m~/miniconda3/lib/python3.11/site-packages/pandas/core/internals/managers.py:225[0m, in [0;36mBaseBlockManager.set_axis[0;34m(self, axis, new_labels)[0m
[1;32m    223[0m [38;5;28;01mdef[39;00m [38;5;21mset_axis[39m([38;5;28mself[39m, axis: AxisInt, new_labels: Index) [38;5;241m-[39m[38;5;241m>[39m [38;5;28;01mNone[39;00m:
[1;32m    224[0m     [38;5;66;03m# Caller is responsible for ensuring we have an Index object.[39;00m
[0;32m--> 225[0m     [38;5;28mself[39m[38;5;241m.[39m_validate_set_axis(axis, new_labels)
[1;32m    226[0m     [38;5;28mself[39m[38;5;241m.[39maxes[axis] [38;5;241m=[39m new_labels

File [0;32m~/miniconda3/lib/python3.11/site-packages/pandas/core/internals/base.py:70[0m, in [0;36mDataManager._validate_set_axis[0;34m(self, axis, new_labels)[0m
[1;32m     67[0m     [38;5;28;01mpass[39;00m
[1;32m     69[0m [38;5;28;01melif[39;00m new_len [38;5;241m!=[39m old_len:
[0;32m---> 70[0m     [38;5;28;01mraise[39;00m [38;5;167;01mValueError[39;00m(
[1;32m     71[0m         [38;5;124mf[39m[38;5;124m"[39m[38;5;124mLength mismatch: Expected axis has [39m[38;5;132;01m{[39;00mold_len[38;5;132;01m}[39;00m[38;5;124m elements, new [39m[38;5;124m"[39m
[1;32m     72[0m         [38;5;124mf[39m[38;5;124m"[39m[38;5;124mvalues have [39m[38;5;132;01m{[39;00mnew_len[38;5;132;01m}[39;00m[38;5;124m elements[39m[38;5;124m"[39m
[1;32m     73[0m     )

[0;31mValueError[0m: Length mismatch: Expected axis has 150 elements, new values have 25 elements
ValueError: Length mismatch: Expected axis has 150 elements, new values have 25 elements

